b'Traceback (most recent call last):\n  File "/root/.vscode-server/extensions/ms-python.debugpy-2025.4.1-linux-x64/bundled/libs/debugpy/_vendored/pydevd/pydevd.py", line 3710, in <module>\n    main()\n  File "/root/.vscode-server/extensions/ms-python.debugpy-2025.4.1-linux-x64/bundled/libs/debugpy/_vendored/pydevd/pydevd.py", line 3695, in main\n    globals = debugger.run(setup["file"], None, None, is_module)\n  File "/root/.vscode-server/extensions/ms-python.debugpy-2025.4.1-linux-x64/bundled/libs/debugpy/_vendored/pydevd/pydevd.py", line 2691, in run\n    return self._exec(is_module, entry_point_fn, module_name, file, globals, locals)\n  File "/root/.vscode-server/extensions/ms-python.debugpy-2025.4.1-linux-x64/bundled/libs/debugpy/_vendored/pydevd/pydevd.py", line 2699, in _exec\n    globals = pydevd_runpy.run_path(file, globals, "__main__")\n  File "/root/.vscode-server/extensions/ms-python.debugpy-2025.4.1-linux-x64/bundled/libs/debugpy/_vendored/pydevd/_pydevd_bundle/pydevd_runpy.py", line 309, in run_path\n    code, fname = _get_code_from_file(run_name, path_name)\n  File "/root/.vscode-server/extensions/ms-python.debugpy-2025.4.1-linux-x64/bundled/libs/debugpy/_vendored/pydevd/_pydevd_bundle/pydevd_runpy.py", line 278, in _get_code_from_file\n    with io_open_code(decoded_path) as f:\nFileNotFoundError: [Errno 2] No such file or directory: \'/var/lib/dingoops/ansible-deploy/inventory/test-123/hosts\'\n'